<?xml version="1.0" ?>
<robot name="hand">
    <link name="world" />
    <link name="base">
        <!-- <inertial>
            <origin rpy="0 0 0" xyz="0 0 0.05"/>
            <mass value="2.9"/>
            <inertia ixx="0.1" ixy="0" ixz="0" iyy="0.1" iyz="0" izz="0.1"/>
        </inertial> -->
        <!-- <visual>
            <origin xyz="0 0 0" rpy="0 0 0" />
            <geometry>
                <box size="0.02 0.02 0.02" />
            </geometry>
        </visual>
        <collision>
            <origin xyz="0 0 0" rpy="0 0 0" />
            <geometry>
                <box size="0.02 0.02 0.02" />
            </geometry>
        </collision> -->
    </link>
    <link name="link1">
        <!-- <inertial>
            <origin rpy="0 0 0" xyz="0 -0.04 -0.05"/>
            <mass value="2.7"/>
            <inertia ixx="0.1" ixy="0" ixz="0" iyy="0.1" iyz="0" izz="0.1"/>
        </inertial> -->
        <visual>
            <origin xyz="0 0 0.15" rpy="0 0 0"/>
            <geometry>
                <cylinder radius="0.01" length="0.3"/>
            </geometry>
        </visual>
        <collision>
            <origin xyz="0 0 0.15" rpy="0 0 0"/>
            <geometry>
                <cylinder radius="0.01" length="0.3"/>
            </geometry>
        </collision>
    </link>
    <joint name="fixture" type="fixed">
        <parent link="world" />
        <child link="base" />
    </joint>
    <joint name="joint1" type="revolute">
        <parent link="base" />
        <child link="link1" />
        <origin xyz="0 0 0.01" rpy="0 0 0" />
        <limit effort="87" velocity="2.1750"/>
        <!-- <safety_controller k_position="100.0" k_velocity="40.0" soft_lower_limit="-2.8973" soft_upper_limit="2.8973"/> -->
        <!-- <axis xyz="1 0 0" /> -->
    </joint>
</robot>