<?xml version="1.0" ?>
<robot name="hand">
	<material name="green">
		<color rgba="0 0.8 0 0.5"/>
	</material>
	<link name="base" />
	<link name="x_tran_link" />
	<link name="y_tran_link" />
	<link name="z_tran_link" />
	<link name="x_rot_link" />
	<link name="y_rot_link" />
	<link name="z_rot_link" />
	<link name="hand_link">
		<inertial>
			<origin rpy="0 0 0" xyz="0 0 0.04"/>
			<mass value=".81"/>
			<inertia ixx="0.1" ixy="0" ixz="0" iyy="0.1" iyz="0" izz="0.1"/>
		</inertial>
		<visual>
			<geometry>
				<mesh filename="/meshes/collision/hand.stl"/>
			</geometry>
			<material name="green" />
			<origin xyz="0.0 0.0 0.0" rpy="0.0 0.0 1.5708"/>
		</visual>
		<collision>
			<geometry>
				<mesh filename="/meshes/collision/hand.stl"/>
			</geometry>
			<origin xyz="0.0 0.0 0.0" rpy="0.0 0.0 1.5708"/>
		</collision>
	</link>
	<link name="rightfinger_link">
		<contact>
			<friction_anchor/>
			<stiffness value="30000.0"/>
			<damping value="1000.0"/>
			<spinning_friction value="0.1"/>
			<lateral_friction value="1.0"/>
		</contact>
		<inertial>
			<origin rpy="0 0 0" xyz="0 -0.01 0.02"/>
			<mass value="0.1"/>
			<inertia ixx="0.1" ixy="0" ixz="0" iyy="0.1" iyz="0" izz="0.1"/>
		</inertial>
		<visual>
			<origin rpy="0 0 1.5708" xyz="0 0 0"/>
			<geometry>
				<mesh filename="/meshes/collision/finger.obj"/>
			</geometry>
		</visual>
		<collision>
			<origin rpy="0 0 1.5708" xyz="0 0 0"/>
			<geometry>
				<mesh filename="/meshes/collision/finger.obj"/>
			</geometry>
		</collision>
	</link>
	<link name="leftfinger_link">
		<contact>
			<friction_anchor/>
			<stiffness value="30000.0"/>
			<damping value="1000.0"/>
			<spinning_friction value="0.1"/>
			<lateral_friction value="1.0"/>
		</contact>
		<inertial>
			<origin rpy="0 0 0" xyz="0 0.01 0.02"/>
			<mass value="0.1"/>
			<inertia ixx="0.1" ixy="0" ixz="0" iyy="0.1" iyz="0" izz="0.1"/>
		</inertial>
		<visual>
			<origin xyz="0.0 0.0 0.0" rpy="0.0 0.0 -1.5708"/>
			<geometry>
				<mesh filename="/meshes/collision/finger.obj"/>
			</geometry>
		</visual>
		<collision>
			<origin xyz="0.0 0.0 0.0" rpy="0.0 0.0 -1.5708"/>
			<geometry>
				<mesh filename="/meshes/collision/finger.obj"/>
			</geometry>
		</collision>
	</link>

	<joint name="base_to_x_rot" type="fixed">
		<!-- <origin xyz="0.0 0.0 0.2" rpy="0.0 3.14159 0.0"/> -->
		<origin xyz="0.0 0.0 0.0" rpy="0.0 0.0 0.0"/>
		<parent link="base"/>
		<child link="x_tran_link"/>
	</joint>
	<joint name="x_tran_to_y_tran" type="prismatic">
		<parent link="x_tran_link"/>
		<child link="y_tran_link"/>
		<axis xyz="1.0 0.0 0.0"/>
		<limit effort="10" velocity="0.1"/>
	</joint>
	<joint name="y_tran_to_z_tran" type="prismatic">
		<parent link="y_tran_link"/>
		<child link="z_tran_link"/>
		<axis xyz="0.0 1.0 0.0"/>
		<limit effort="10" velocity="0.1"/>
	</joint>
	<joint name="z_tran_to_hand" type="prismatic">
		<parent link="z_tran_link"/>
		<child link="x_rot_link"/>
		<axis xyz="0.0 0.0 1.0"/>
		<limit effort="10" velocity="0.1"/>
	</joint>
	<joint name="x_rot_to_y_rot" type="revolute">
		<parent link="x_rot_link"/>
		<child link="y_rot_link"/>
		<axis xyz="1.0 0.0 0.0"/>
		<limit effort="10" velocity="0.1"/>
	</joint>
	<joint name="y_rot_to_z_rot" type="revolute">
		<parent link="y_rot_link"/>
		<child link="z_rot_link"/>
		<axis xyz="0.0 1.0 0.0"/>
		<limit effort="10" velocity="0.1"/>
	</joint>
	<joint name="z_rot_to_x_tran" type="revolute">
		<parent link="z_rot_link"/>
		<child link="hand_link"/>
		<axis xyz="0.0 0.0 1.0"/>
		<limit effort="10" velocity="0.1"/>
	</joint>
	<joint name="panda_finger_joint1" type="prismatic">
		<parent link="hand_link"/>
		<child link="leftfinger_link"/>
		<origin rpy="0 0 0" xyz="0 0 0.0584"/>
		<axis xyz="1 0 0"/>
		<limit effort="20" lower="0.0" upper="0.04" velocity="0.2"/>
	</joint>
	<joint name="panda_finger_joint2" type="prismatic">
		<parent link="hand_link"/>
		<child link="rightfinger_link"/>
		<origin rpy="0 0 0" xyz="0 0 0.0584"/>
		<axis xyz="-1 0 0"/>
		<limit effort="20" lower="0.0" upper="0.04" velocity="0.2"/>
		<mimic joint="panda_finger_joint1"/>
	</joint>
</robot>